Workbook

Sheet Dual Clock
A1: Powered Silicon Dual Clock
A2: BUY CLOCK: irreversible physical infrastructure implies future silicon. SELL CLOCK: hardware deliveries/revenue outrun energizable capacity and power becomes binding again.
A4: CURRENT READ — SEP 4, 2026
A5: BUY CLOCK | E5: MODEL INPUTS
A6: ACTIVE / ACCUMULATION | E6: Current sell convergence score | F6: =MAX('Sell Backtest'!G16:G20) | I6: 0–5
A7: New power/electrical tranches remain contracted and physically moving toward 2027. | E7: Latest Fwd 6M hardware/power ratio | F7: =IFERROR(LOOKUP(2,1/('Coverage Calendar'!G5:G40<>""),'Coverage Calendar'!G5:G40),"NO DATA") | I7: x
A8: SELL CLOCK | E8: Current coverage risk band | F8: =IFERROR(LOOKUP(2,1/('Coverage Calendar'!H5:H40<>"NO DATA"),'Coverage Calendar'!H5:H40),"NO DATA")
A9: SELL CLOCK | E9: SOXX Jun-22 peak | F9: 655.01 | I9: $
A10: WATCH — NOT RED | E10: Current model regime | F10: Re-accumulation after reset / next infrastructure tranche
A11: NEXT CONFIRMATION
A12: DELIVERY COVERAGE | E12: ACTION FRAMEWORK
A13: Track Rubin/server/HBM delivery windows against usable IT MW entering service. | E13: ACCUMULATE | F13: Power/generation and long-lead electrical/cooling commitments become irreversible while semis remain weak.
A14: FAIL CONDITION | E14: ADD | F14: Silicon allocations / HBM / CoWoS / server orders confirm the physical build is converting to hardware.
A15: POWER CLOCK SLIPS AGAIN | E15: STOP ADDING | F15: Sell score reaches 3: physical slippage + hardware acceleration are both visible.
A16: If hardware schedule firms while CODs slip or grid interventions escalate, sell score should climb quickly. | E16: REDUCE | F16: Sell score reaches 4 or forward hardware/power coverage enters ORANGE.
E17: EXIT / HEDGE | F17: Sell score reaches 5 or coverage is RED and a system-level constraint is confirmed.
A20: LAST-CYCLE PROOF OF CONCEPT
A21: May 4 | B21: JPM: >60% of 2027 capacity not started; 7% delayed | I21: 49 days before peak
A22: May 5 | B22: Eaton: 32 GW under construction vs 228 GW backlog | I22: 48 days before peak
A23: May 20 | B23: NVIDIA: $75.2B Data Center revenue | I23: 33 days before peak
A24: May 28 | B24: Dell: $24.4B AI orders / $16.1B revenue / $51.3B backlog | I24: 25 days before peak
A25: Jun 18 | B25: FERC acts across all six RTO/ISOs on large-load integration | I25: 4 days before peak
A26: Jun 22 | B26: SOXX closes 655.01; intraday high 655.95 | I26: Peak
A29: HOW TO UPDATE WEEKLY
A30: 1. Add any hardware delivery schedule with a credible start/end window to Hardware Deliveries. Do not use backlog dollars without a delivery clock.
A31: 2. Add any contracted generation / grid energization schedule to Power Deliveries. Use project-specific PUE / reserve assumptions when disclosed.
A32: 3. Coverage Calendar converts both into monthly IT MW and a forward 6-month hardware-to-power ratio.
A33: 4. Add independent sell-warning events to Sell Backtest. Repeated articles about the same underlying constraint do not add score.
A34: 5. The trade is symmetrical: buy when physical capital becomes irreversible before silicon revenue; sell when silicon delivery outruns power readiness.

Sheet Dashboard
A1: Physical → Silicon Timing Model
A2: Goal: identify WHEN physical data-center infrastructure orders are far enough along to front-run chip orders, chip revenue and semiconductor equity re-ratings.
A4: Preliminary result
A5: Sample | B5: N | C5: Avg 3M SOXX | D5: Median 3M | E5: Avg 6M SOXX | F5: Avg lead to next >=10% month
A6: ='Event Study'!A6 | B6: ='Event Study'!B6 | C6: ='Event Study'!D6 | D6: ='Event Study'!E6 | E6: ='Event Study'!F6 | F6: ='Event Study'!H6
A7: ='Event Study'!A7 | B7: ='Event Study'!B7 | C7: ='Event Study'!D7 | D7: ='Event Study'!E7 | E7: ='Event Study'!F7 | F7: ='Event Study'!H7
A8: ='Event Study'!A8 | B8: ='Event Study'!B8 | C8: ='Event Study'!D8 | D8: ='Event Study'!E8 | E8: ='Event Study'!F8 | F8: ='Event Study'!H8
A9: ='Event Study'!A9 | B9: ='Event Study'!B9 | C9: ='Event Study'!D9 | D9: ='Event Study'!E9 | E9: ='Event Study'!F9 | F9: ='Event Study'!H9
A11: Working trading clock
A12: 1 | B12: Power/generation contract becomes firm | E12: Earliest signal. Direct behind-the-meter orders can establish a hard delivery clock ~8–20+ months before power-on.
A13: 2 | B13: Electrical/cooling orders accelerate | E13: Best preliminary public signal. In the Jul-2025–Feb-2026 sample, the next >=10% SOXX month arrived about 2 months later on average.
A14: 3 | B14: HBM / CoWoS / GPU allocation confirms | E14: Procurement can be 6–18 months ahead of deployment; useful confirmation, but semis may already be moving.
A15: 4 | B15: Server backlog / shipments surge | E15: Late confirmation. Chip revenue is already being recognized or imminent.
A16: 5 | B16: Compute goes live | E16: Too late for the entry signal; this is where the physical build begins monetizing.
A19: What the backtest says — and does not say
A20: Evidence | B20: The power-constrained 2025H2–2026 upstream sample shows much stronger 3M/6M SOXX forward returns than the 2023–24 demand-led sample. This is consistent with the thesis that physical capacity became the gating variable.
A21: Best current signal | B21: Watch VRT/ETN/CAT/MEP order inflections and firm power-delivery commitments BEFORE Dell/server revenue and HBM/CoWoS confirmations become obvious.
A22: Do not overread | B22: The sample is small and clustered. Multiple events reflect the same build cycle. The regime split is ex post. This is a countdown framework, not a proven factor model.
A23: New: Dual Clock adds a sell-side hardware-vs-power constraint model and project-level delivery ledgers.

Sheet Market Data
A1: Month | B1: SOXX Close | C1: Monthly Return | D1: Strong Month >=10% | E1: Upstream Events | F1: Bridge/Confirm Events | G1: Source URL
A2: 44896 | B2: 113.26 | D2: =IF(C2>=10%,1,0) | E2: =COUNTIFS('Supplier Signals'!$P$2:$P$100,A2,'Supplier Signals'!$F$2:$F$100,"Upstream physical") | F2: =COUNTIFS('Supplier Signals'!$P$2:$P$100,A2,'Supplier Signals'!$F$2:$F$100,"<>Upstream physical") | G2: https://www.statmuse.com/money/ask?q=soxx+returns+2011-2024
A3: 44927 | B3: 131.39 | C3: =B3/B2-1 | D3: =IF(C3>=10%,1,0) | E3: =COUNTIFS('Supplier Signals'!$P$2:$P$100,A3,'Supplier Signals'!$F$2:$F$100,"Upstream physical") | F3: =COUNTIFS('Supplier Signals'!$P$2:$P$100,A3,'Supplier Signals'!$F$2:$F$100,"<>Upstream physical") | G3: https://www.statmuse.com/money/ask?q=soxx+returns+2011-2024
A4: 44958 | B4: 133.39 | C4: =B4/B3-1 | D4: =IF(C4>=10%,1,0) | E4: =COUNTIFS('Supplier Signals'!$P$2:$P$100,A4,'Supplier Signals'!$F$2:$F$100,"Upstream physical") | F4: =COUNTIFS('Supplier Signals'!$P$2:$P$100,A4,'Supplier Signals'!$F$2:$F$100,"<>Upstream physical") | G4: https://www.statmuse.com/money/ask?q=soxx+returns+2011-2024
A5: 44986 | B5: 145.1 | C5: =B5/B4-1 | D5: =IF(C5>=10%,1,0) | E5: =COUNTIFS('Supplier Signals'!$P$2:$P$100,A5,'Supplier Signals'!$F$2:$F$100,"Upstream physical") | F5: =COUNTIFS('Supplier Signals'!$P$2:$P$100,A5,'Supplier Signals'!$F$2:$F$100,"<>Upstream physical") | G5: https://www.statmuse.com/money/ask?q=soxx+returns+2011-2024
A6: 45017 | B6: 134.48 | C6: =B6/B5-1 | D6: =IF(C6>=10%,1,0) | E6: =COUNTIFS('Supplier Signals'!$P$2:$P$100,A6,'Supplier Signals'!$F$2:$F$100,"Upstream physical") | F6: =COUNTIFS('Supplier Signals'!$P$2:$P$100,A6,'Supplier Signals'!$F$2:$F$100,"<>Upstream physical") | G6: https://www.statmuse.com/money/ask?q=soxx+returns+2011-2024
A7: 45047 | B7: 155.55 | C7: =B7/B6-1 | D7: =IF(C7>=10%,1,0) | E7: =COUNTIFS('Supplier Signals'!$P$2:$P$100,A7,'Supplier Signals'!$F$2:$F$100,"Upstream physical") | F7: =COUNTIFS('Supplier Signals'!$P$2:$P$100,A7,'Supplier Signals'!$F$2:$F$100,"<>Upstream physical") | G7: https://www.statmuse.com/money/ask?q=soxx+returns+2011-2024
A8: 45078 | B8: 165.75 | C8: =B8/B7-1 | D8: =IF(C8>=10%,1,0) | E8: =COUNTIFS('Supplier Signals'!$P$2:$P$100,A8,'Supplier Signals'!$F$2:$F$100,"Upstream physical") | F8: =COUNTIFS('Supplier Signals'!$P$2:$P$100,A8,'Supplier Signals'!$F$2:$F$100,"<>Upstream physical") | G8: https://www.statmuse.com/money/ask?q=soxx+returns+2011-2024
A9: 45108 | B9: 174.91 | C9: =B9/B8-1 | D9: =IF(C9>=10%,1,0) | E9: =COUNTIFS('Supplier Signals'!$P$2:$P$100,A9,'Supplier Signals'!$F$2:$F$100,"Upstream physical") | F9: =COUNTIFS('Supplier Signals'!$P$2:$P$100,A9,'Supplier Signals'!$F$2:$F$100,"<>Upstream physical") | G9: https://www.statmuse.com/money/ask?q=soxx+returns+2011-2024
A10: 45139 | B10: 166.86 | C10: =B10/B9-1 | D10: =IF(C10>=10%,1,0) | E10: =COUNTIFS('Supplier Signals'!$P$2:$P$100,A10,'Supplier Signals'!$F$2:$F$100,"Upstream physical") | F10: =COUNTIFS('Supplier Signals'!$P$2:$P$100,A10,'Supplier Signals'!$F$2:$F$100,"<>Upstream physical") | G10: https://www.statmuse.com/money/ask?q=soxx+returns+2011-2024
A11: 45170 | B11: 155.32 | C11: =B11/B10-1 | D11: =IF(C11>=10%,1,0) | E11: =COUNTIFS('Supplier Signals'!$P$2:$P$100,A11,'Supplier Signals'!$F$2:$F$100,"Upstream physical") | F11: =COUNTIFS('Supplier Signals'!$P$2:$P$100,A11,'Supplier Signals'!$F$2:$F$100,"<>Upstream physical") | G11: https://www.statmuse.com/money/ask?q=soxx+returns+2011-2024
A12: 45200 | B12: 145.07 | C12: =B12/B11-1 | D12: =IF(C12>=10%,1,0) | E12: =COUNTIFS('Supplier Signals'!$P$2:$P$100,A12,'Supplier Signals'!$F$2:$F$100,"Upstream physical") | F12: =COUNTIFS('Supplier Signals'!$P$2:$P$100,A12,'Supplier Signals'!$F$2:$F$100,"<>Upstream physical") | G12: https://www.statmuse.com/money/ask?q=soxx+returns+2011-2024
A13: 45231 | B13: 168.43 | C13: =B13/B12-1 | D13: =IF(C13>=10%,1,0) | E13: =COUNTIFS('Supplier Signals'!$P$2:$P$100,A13,'Supplier Signals'!$F$2:$F$100,"Upstream physical") | F13: =COUNTIFS('Supplier Signals'!$P$2:$P$100,A13,'Supplier Signals'!$F$2:$F$100,"<>Upstream physical") | G13: https://www.statmuse.com/money/ask?q=soxx+returns+2011-2024
A14: 45261 | B14: 189.28 | C14: =B14/B13-1 | D14: =IF(C14>=10%,1,0) | E14: =COUNTIFS('Supplier Signals'!$P$2:$P$100,A14,'Supplier Signals'!$F$2:$F$100,"Upstream physical") | F14: =COUNTIFS('Supplier Signals'!$P$2:$P$100,A14,'Supplier Signals'!$F$2:$F$100,"<>Upstream physical") | G14: https://www.statmuse.com/money/ask?q=soxx+returns+2011-2024
... A46: 46235 | B46: 511.04 | C46: =B46/B45-1 | D46: =IF(C46>=10%,1,0) | E46: =COUNTIFS('Supplier Signals'!$P$2:$P$100,A46,'Supplier Signals'!$F$2:$F$100,"Upstream physical") | F46: =COUNTIFS('Supplier Signals'!$P$2:$P$100,A46,'Supplier Signals'!$F$2:$F$100,"<>Upstream physical") | G46: https://www.statmuse.com/money/ask?q=What%27s+the+all-time+high+for+SOXX%3F

Sheet Supplier Signals
A1: ID | B1: Event Date | C1: Company | D1: Ticker | E1: Layer | F1: Signal Type | G1: Backtest? | H1: Regime | I1: Event / Metric | J1: Magnitude | K1: Confidence (1-5) | L1: Clock Stage | M1: Lead to Chip Rev Min (mo) | N1: Lead to Chip Rev Max (mo) | O1: Source URL | P1: Event Month | Q1: SOXX Event Close | R1: 1M Fwd | S1: 3M Fwd | T1: 6M Fwd | U1: 9M Fwd | V1: Next >=10% SOXX Month | W1: Months to Next >=10% | X1: Interpretation
A2: 1 | B2: 44965 | C2: Eaton | D2: ETN | E2: Electrical | F2: Upstream physical | G2: 1 | H2: Demand-led | I2: Electrical Americas orders/backlog surge with explicit data-center strength | J2: Orders +34% TTM; backlog +87% YoY | K2: 4 | L2: Electrical / power distribution | M2: 3 | N2: 12 | O2: https://www.eaton.com/us/en-us/company/news-insights/news-releases/2023/eaton-reports-record-fourth-quarter-2022-results.html | P2: =DATE(YEAR(B2),MONTH(B2),1) | Q2: =IFERROR(INDEX('Market Data'!$B$2:$B$60,MATCH(P2,'Market Data'!$A$2:$A$60,0)),"") | R2: =IFERROR(INDEX('Market Data'!$B$2:$B$60,MATCH(EDATE(P2,1),'Market Data'!$A$2:$A$60,0))/Q2-1,"") | S2: =IFERROR(INDEX('Market Data'!$B$2:$B$60,MATCH(EDATE(P2,3),'Market Data'!$A$2:$A$60,0))/Q2-1,"") | T2: =IFERROR(INDEX('Market Data'!$B$2:$B$60,MATCH(EDATE(P2,6),'Market Data'!$A$2:$A$60,0))/Q2-1,"") | U2: =IFERROR(INDEX('Market Data'!$B$2:$B$60,MATCH(EDATE(P2,9),'Market Data'!$A$2:$A$60,0))/Q2-1,"") | V2: =IFERROR(MINIFS('Market Data'!$A$2:$A$60,'Market Data'!$A$2:$A$60,">"&P2,'Market Data'!$D$2:$D$60,1),"") | W2: =IF(V2="","",DATEDIF(P2,V2,"m")) | X2: Historical upstream signal; often concurrent rather than leading in demand-led phase.
A3: 2 | B3: 45224 | C3: Vertiv | D3: VRT | E3: Cooling / power | F3: Upstream physical | G3: 1 | H3: Demand-led | I3: Q3 critical-infrastructure orders and backlog rise | J3: Orders +11% YoY; backlog $5.0B | K3: 4 | L3: Cooling / UPS / power | M3: 3 | N3: 12 | O3: https://investors.vertiv.com/news/news-details/2023/Vertiv-Reports-Strong-Third-Quarter-Results-and-Raises-Full-Year-2023-Outlook/default.aspx | P3: =DATE(YEAR(B3),MONTH(B3),1) | Q3: =IFERROR(INDEX('Market Data'!$B$2:$B$60,MATCH(P3,'Market Data'!$A$2:$A$60,0)),"") | R3: =IFERROR(INDEX('Market Data'!$B$2:$B$60,MATCH(EDATE(P3,1),'Market Data'!$A$2:$A$60,0))/Q3-1,"") | S3: =IFERROR(INDEX('Market Data'!$B$2:$B$60,MATCH(EDATE(P3,3),'Market Data'!$A$2:$A$60,0))/Q3-1,"") | T3: =IFERROR(INDEX('Market Data'!$B$2:$B$60,MATCH(EDATE(P3,6),'Market Data'!$A$2:$A$60,0))/Q3-1,"") | U3: =IFERROR(INDEX('Market Data'!$B$2:$B$60,MATCH(EDATE(P3,9),'Market Data'!$A$2:$A$60,0))/Q3-1,"") | V3: =IFERROR(MINIFS('Market Data'!$A$2:$A$60,'Market Data'!$A$2:$A$60,">"&P3,'Market Data'!$D$2:$D$60,1),"") | W3: =IF(V3="","",DATEDIF(P3,V3,"m")) | X3: Historical upstream signal; often concurrent rather than leading in demand-led phase.
A4: 3 | B4: 45343 | C4: Vertiv | D4: VRT | E4: Cooling / power | F4: Upstream physical | G4: 1 | H4: Demand-led | I4: Q4 critical-infrastructure orders accelerate | J4: Orders +23% YoY; book-to-bill 1.3x; backlog $5.5B | K4: 4 | L4: Cooling / UPS / power | M4: 3 | N4: 12 | O4: https://investors.vertiv.com/news/news-details/2024/Vertiv-Reports-Strong-Fourth-Quarter-Results-and-Provides-Full-Year-2024-Outlook/default.aspx | P4: =DATE(YEAR(B4),MONTH(B4),1) | Q4: =IFERROR(INDEX('Market Data'!$B$2:$B$60,MATCH(P4,'Market Data'!$A$2:$A$60,0)),"") | R4: =IFERROR(INDEX('Market Data'!$B$2:$B$60,MATCH(EDATE(P4,1),'Market Data'!$A$2:$A$60,0))/Q4-1,"") | S4: =IFERROR(INDEX('Market Data'!$B$2:$B$60,MATCH(EDATE(P4,3),'Market Data'!$A$2:$A$60,0))/Q4-1,"") | T4: =IFERROR(INDEX('Market Data'!$B$2:$B$60,MATCH(EDATE(P4,6),'Market Data'!$A$2:$A$60,0))/Q4-1,"") | U4: =IFERROR(INDEX('Market Data'!$B$2:$B$60,MATCH(EDATE(P4,9),'Market Data'!$A$2:$A$60,0))/Q4-1,"") | V4: =IFERROR(MINIFS('Market Data'!$A$2:$A$60,'Market Data'!$A$2:$A$60,">"&P4,'Market Data'!$D$2:$D$60,1),"") | W4: =IF(V4="","",DATEDIF(P4,V4,"m")) | X4: Historical upstream signal; often concurrent rather than leading in demand-led phase.
A5: 4 | B5: 45343 | C5: SK hynix | D5: 000660.KS | E5: HBM | F5: Bridge / chip procurement | G5: 0 | H5: Demand-led | I5: HBM production already sold out; planning next year | J5: 2024 HBM planned output sold out; already preparing 2025 | K5: 5 | L5: HBM allocation | M5: 0 | N5: 12 | O5: https://news.skhynix.com/en/new-leadership-spotlight-vice-president-kitae-kim-head-of-hbm-sales-marketing/ | P5: =DATE(YEAR(B5),MONTH(B5),1) | Q5: =IFERROR(INDEX('Market Data'!$B$2:$B$60,MATCH(P5,'Market Data'!$A$2:$A$60,0)),"") | R5: =IFERROR(INDEX('Market Data'!$B$2:$B$60,MATCH(EDATE(P5,1),'Market Data'!$A$2:$A$60,0))/Q5-1,"") | S5: =IFERROR(INDEX('Market Data'!$B$2:$B$60,MATCH(EDATE(P5,3),'Market Data'!$A$2:$A$60,0))/Q5-1,"") | T5: =IFERROR(INDEX('Market Data'!$B$2:$B$60,MATCH(EDATE(P5,6),'Market Data'!$A$2:$A$60,0))/Q5-1,"") | U5: =IFERROR(INDEX('Market Data'!$B$2:$B$60,MATCH(EDATE(P5,9),'Market Data'!$A$2:$A$60,0))/Q5-1,"") | V5: =IFERROR(MINIFS('Market Data'!$A$2:$A$60,'Market Data'!$A$2:$A$60,">"&P5,'Market Data'!$D$2:$D$60,1),"") | W5: =IF(V5="","",DATEDIF(P5,V5,"m")) | X5: Procurement bridge; validates physical demand but may be late for equity entry.
A6: 5 | B6: 45351 | C6: Dell | D6: DELL | E6: Servers / racks | F6: Bridge / systems | G6: 0 | H6: Demand-led | I6: AI server backlog nearly doubles | J6: AI orders +~40% sequential; backlog $2.9B | K6: 5 | L6: Server / rack orders | M6: 0 | N6: 6 | O6: https://www.dell.com/en-us/dt/corporate/newsroom/announcements/detailpage.press-releases~usa~2024~02~dell-technologies-delivers-fourth-quarter-and-full-year-fiscal-2024-financial-results.htm | P6: =DATE(YEAR(B6),MONTH(B6),1) | Q6: =IFERROR(INDEX('Market Data'!$B$2:$B$60,MATCH(P6,'Market Data'!$A$2:$A$60,0)),"") | R6: =IFERROR(INDEX('Market Data'!$B$2:$B$60,MATCH(EDATE(P6,1),'Market Data'!$A$2:$A$60,0))/Q6-1,"") | S6: =IFERROR(INDEX('Market Data'!$B$2:$B$60,MATCH(EDATE(P6,3),'Market Data'!$A$2:$A$60,0))/Q6-1,"") | T6: =IFERROR(INDEX('Market Data'!$B$2:$B$60,MATCH(EDATE(P6,6),'Market Data'!$A$2:$A$60,0))/Q6-1,"") | U6: =IFERROR(INDEX('Market Data'!$B$2:$B$60,MATCH(EDATE(P6,9),'Market Data'!$A$2:$A$60,0))/Q6-1,"") | V6: =IFERROR(MINIFS('Market Data'!$A$2:$A$60,'Market Data'!$A$2:$A$60,">"&P6,'Market Data'!$D$2:$D$60,1),"") | W6: =IF(V6="","",DATEDIF(P6,V6,"m")) | X6: Procurement bridge; validates physical demand but may be late for equity entry.
A7: 6 | B7: 45406 | C7: Vertiv | D7: VRT | E7: Cooling / power | F7: Upstream physical | G7: 1 | H7: Demand-led | I7: Q1 AI-driven infrastructure orders jump | J7: Orders +60% YoY; book-to-bill 1.5x; backlog $6.3B | K7: 5 | L7: Cooling / UPS / power | M7: 3 | N7: 12 | O7: https://investors.vertiv.com/news/news-details/2024/Vertiv-Reports-60-Organic-Orders-Growth-8-Net-Sales-Growth-in-First-Quarter-Updates-Full-Year-2024-Outlook/default.aspx | P7: =DATE(YEAR(B7),MONTH(B7),1) | Q7: =IFERROR(INDEX('Market Data'!$B$2:$B$60,MATCH(P7,'Market Data'!$A$2:$A$60,0)),"") | R7: =IFERROR(INDEX('Market Data'!$B$2:$B$60,MATCH(EDATE(P7,1),'Market Data'!$A$2:$A$60,0))/Q7-1,"") | S7: =IFERROR(INDEX('Market Data'!$B$2:$B$60,MATCH(EDATE(P7,3),'Market Data'!$A$2:$A$60,0))/Q7-1,"") | T7: =IFERROR(INDEX('Market Data'!$B$2:$B$60,MATCH(EDATE(P7,6),'Market Data'!$A$2:$A$60,0))/Q7-1,"") | U7: =IFERROR(INDEX('Market Data'!$B$2:$B$60,MATCH(EDATE(P7,9),'Market Data'!$A$2:$A$60,0))/Q7-1,"") | V7: =IFERROR(MINIFS('Market Data'!$A$2:$A$60,'Market Data'!$A$2:$A$60,">"&P7,'Market Data'!$D$2:$D$60,1),"") | W7: =IF(V7="","",DATEDIF(P7,V7,"m")) | X7: Historical upstream signal; often concurrent rather than leading in demand-led phase.
A8: 7 | B8: 45442 | C8: Dell | D8: DELL | E8: Servers / racks | F8: Bridge / systems | G8: 0 | H8: Demand-led | I8: AI server order and shipment ramp | J8: Orders $2.6B; shipments $1.7B; backlog $3.8B | K8: 5 | L8: Server / rack orders | M8: 0 | N8: 6 | O8: https://investors.delltechnologies.com/news-releases/news-release-details/dell-technologies-delivers-first-quarter-fiscal-2025-financial | P8: =DATE(YEAR(B8),MONTH(B8),1) | Q8: =IFERROR(INDEX('Market Data'!$B$2:$B$60,MATCH(P8,'Market Data'!$A$2:$A$60,0)),"") | R8: =IFERROR(INDEX('Market Data'!$B$2:$B$60,MATCH(EDATE(P8,1),'Market Data'!$A$2:$A$60,0))/Q8-1,"") | S8: =IFERROR(INDEX('Market Data'!$B$2:$B$60,MATCH(EDATE(P8,3),'Market Data'!$A$2:$A$60,0))/Q8-1,"") | T8: =IFERROR(INDEX('Market Data'!$B$2:$B$60,MATCH(EDATE(P8,6),'Market Data'!$A$2:$A$60,0))/Q8-1,"") | U8: =IFERROR(INDEX('Market Data'!$B$2:$B$60,MATCH(EDATE(P8,9),'Market Data'!$A$2:$A$60,0))/Q8-1,"") | V8: =IFERROR(MINIFS('Market Data'!$A$2:$A$60,'Market Data'!$A$2:$A$60,">"&P8,'Market Data'!$D$2:$D$60,1),"") | W8: =IF(V8="","",DATEDIF(P8,V8,"m")) | X8: Procurement bridge; validates physical demand but may be late for equity entry.
A9: 8 | B9: 45491 | C9: TSMC | D9: TSM | E9: Advanced packaging | F9: Bridge / chip procurement | G9: 0 | H9: Demand-led | I9: CoWoS expansion confirms accelerator packaging pull | J9: Capacity >2x in 2024; target ~2x or more again in 2025 | K9: 5 | L9: Foundry / CoWoS | M9: 0 | N9: 12 | O9: https://investor.tsmc.com/english/encrypt/files/encrypt_file/reports/2024-08/5122725a56670882d777a8e8bfe0ed247cc55330/TSMC%202Q24%20Transcript.pdf | P9: =DATE(YEAR(B9),MONTH(B9),1) | Q9: =IFERROR(INDEX('Market Data'!$B$2:$B$60,MATCH(P9,'Market Data'!$A$2:$A$60,0)),"") | R9: =IFERROR(INDEX('Market Data'!$B$2:$B$60,MATCH(EDATE(P9,1),'Market Data'!$A$2:$A$60,0))/Q9-1,"") | S9: =IFERROR(INDEX('Market Data'!$B$2:$B$60,MATCH(EDATE(P9,3),'Market Data'!$A$2:$A$60,0))/Q9-1,"") | T9: =IFERROR(INDEX('Market Data'!$B$2:$B$60,MATCH(EDATE(P9,6),'Market Data'!$A$2:$A$60,0))/Q9-1,"") | U9: =IFERROR(INDEX('Market Data'!$B$2:$B$60,MATCH(EDATE(P9,9),'Market Data'!$A$2:$A$60,0))/Q9-1,"") | V9: =IFERROR(MINIFS('Market Data'!$A$2:$A$60,'Market Data'!$A$2:$A$60,">"&P9,'Market Data'!$D$2:$D$60,1),"") | W9: =IF(V9="","",DATEDIF(P9,V9,"m")) | X9: Procurement bridge; validates physical demand but may be late for equity entry.
A10: 9 | B10: 45588 | C10: Vertiv | D10: VRT | E10: Cooling / power | F10: Upstream physical | G10: 1 | H10: Demand-led | I10: Hyperscale and AI/liquid-cooling pipeline stays strong | J10: Q3 orders +17% YoY; TTM +37% | K10: 4 | L10: Cooling / UPS / power | M10: 3 | N10: 12 | O10: https://investors.vertiv.com/news/news-details/2024/Vertiv-Reports-Strong-Third-Quarter-2024-Results-and-Raises-Full-Year-Guidance/default.aspx | P10: =DATE(YEAR(B10),MONTH(B10),1) | Q10: =IFERROR(INDEX('Market Data'!$B$2:$B$60,MATCH(P10,'Market Data'!$A$2:$A$60,0)),"") | R10: =IFERROR(INDEX('Market Data'!$B$2:$B$60,MATCH(EDATE(P10,1),'Market Data'!$A$2:$A$60,0))/Q10-1,"") | S10: =IFERROR(INDEX('Market Data'!$B$2:$B$60,MATCH(EDATE(P10,3),'Market Data'!$A$2:$A$60,0))/Q10-1,"") | T10: =IFERROR(INDEX('Market Data'!$B$2:$B$60,MATCH(EDATE(P10,6),'Market Data'!$A$2:$A$60,0))/Q10-1,"") | U10: =IFERROR(INDEX('Market Data'!$B$2:$B$60,MATCH(EDATE(P10,9),'Market Data'!$A$2:$A$60,0))/Q10-1,"") | V10: =IFERROR(MINIFS('Market Data'!$A$2:$A$60,'Market Data'!$A$2:$A$60,">"&P10,'Market Data'!$D$2:$D$60,1),"") | W10: =IF(V10="","",DATEDIF(P10,V10,"m")) | X10: Historical upstream signal; often concurrent rather than leading in demand-led phase.
A11: 10 | B11: 45688 | C11: Eaton | D11: ETN | E11: Electrical | F11: Upstream physical | G11: 1 | H11: Transition | I11: Data-center electrical order book sharply expands | J11: Data-center TTM orders +75%; backlog +50%; hyperscaler sales +~75% | K11: 5 | L11: Electrical / power distribution | M11: 3 | N11: 12 | O11: https://www.eaton.com/content/dam/eaton/company/investor-relations/quarterly-earnings/filings/2024/q4/4Q-2024-analyst-presentation.pdf | P11: =DATE(YEAR(B11),MONTH(B11),1) | Q11: =IFERROR(INDEX('Market Data'!$B$2:$B$60,MATCH(P11,'Market Data'!$A$2:$A$60,0)),"") | R11: =IFERROR(INDEX('Market Data'!$B$2:$B$60,MATCH(EDATE(P11,1),'Market Data'!$A$2:$A$60,0))/Q11-1,"") | S11: =IFERROR(INDEX('Market Data'!$B$2:$B$60,MATCH(EDATE(P11,3),'Market Data'!$A$2:$A$60,0))/Q11-1,"") | T11: =IFERROR(INDEX('Market Data'!$B$2:$B$60,MATCH(EDATE(P11,6),'Market Data'!$A$2:$A$60,0))/Q11-1,"") | U11: =IFERROR(INDEX('Market Data'!$B$2:$B$60,MATCH(EDATE(P11,9),'Market Data'!$A$2:$A$60,0))/Q11-1,"") | V11: =IFERROR(MINIFS('Market Data'!$A$2:$A$60,'Market Data'!$A$2:$A$60,">"&P11,'Market Data'!$D$2:$D$60,1),"") | W11: =IF(V11="","",DATEDIF(P11,V11,"m")) | X11: Historical upstream signal; often concurrent rather than leading in demand-led phase.
A12: 11 | B12: 45736 | C12: Micron | D12: MU | E12: HBM | F12: Bridge / chip procurement | G12: 0 | H12: Transition | I12: HBM volume commitments extend into next year | J12: 2025 HBM sold out; negotiating 2026 demand | K12: 5 | L12: HBM allocation | M12: 0 | N12: 12 | O12: https://investors.micron.com/static-files/52ce0c07-49dc-4eab-b1d2-a67bde373bca | P12: =DATE(YEAR(B12),MONTH(B12),1) | Q12: =IFERROR(INDEX('Market Data'!$B$2:$B$60,MATCH(P12,'Market Data'!$A$2:$A$60,0)),"") | R12: =IFERROR(INDEX('Market Data'!$B$2:$B$60,MATCH(EDATE(P12,1),'Market Data'!$A$2:$A$60,0))/Q12-1,"") | S12: =IFERROR(INDEX('Market Data'!$B$2:$B$60,MATCH(EDATE(P12,3),'Market Data'!$A$2:$A$60,0))/Q12-1,"") | T12: =IFERROR(INDEX('Market Data'!$B$2:$B$60,MATCH(EDATE(P12,6),'Market Data'!$A$2:$A$60,0))/Q12-1,"") | U12: =IFERROR(INDEX('Market Data'!$B$2:$B$60,MATCH(EDATE(P12,9),'Market Data'!$A$2:$A$60,0))/Q12-1,"") | V12: =IFERROR(MINIFS('Market Data'!$A$2:$A$60,'Market Data'!$A$2:$A$60,">"&P12,'Market Data'!$D$2:$D$60,1),"") | W12: =IF(V12="","",DATEDIF(P12,V12,"m")) | X12: Procurement bridge; validates physical demand but may be late for equity entry.
A13: 12 | B13: 45868 | C13: Vertiv | D13: VRT | E13: Cooling / power | F13: Upstream physical | G13: 1 | H13: Power-constrained | I13: Critical infrastructure orders reaccelerate sequentially | J13: Q2 orders +15% YoY / +11% sequential; backlog $8.5B; B2B ~1.2x | K13: 4 | L13: Cooling / UPS / power | M13: 3 | N13: 12 | O13: https://investors.vertiv.com/news/news-details/2025/Vertiv-Reports-Strong-Orders-Sales-and-EPS-Growth-Raises-Full-Year-Guidance/ | P13: =DATE(YEAR(B13),MONTH(B13),1) | Q13: =IFERROR(INDEX('Market Data'!$B$2:$B$60,MATCH(P13,'Market Data'!$A$2:$A$60,0)),"") | R13: =IFERROR(INDEX('Market Data'!$B$2:$B$60,MATCH(EDATE(P13,1),'Market Data'!$A$2:$A$60,0))/Q13-1,"") | S13: =IFERROR(INDEX('Market Data'!$B$2:$B$60,MATCH(EDATE(P13,3),'Market Data'!$A$2:$A$60,0))/Q13-1,"") | T13: =IFERROR(INDEX('Market Data'!$B$2:$B$60,MATCH(EDATE(P13,6),'Market Data'!$A$2:$A$60,0))/Q13-1,"") | U13: =IFERROR(INDEX('Market Data'!$B$2:$B$60,MATCH(EDATE(P13,9),'Market Data'!$A$2:$A$60,0))/Q13-1,"") | V13: =IFERROR(MINIFS('Market Data'!$A$2:$A$60,'Market Data'!$A$2:$A$60,">"&P13,'Market Data'!$D$2:$D$60,1),"") | W13: =IF(V13="","",DATEDIF(P13,V13,"m")) | X13: Candidate leading signal in power-constrained regime.
... A24: 23 | B24: 46266 | C24: Dell | D24: DELL | E24: Servers / racks | F24: Current late-stage confirmation | G24: 0 | H24: Current | I24: Current cycle is already deep into server monetization | J24: AI orders $60.9B; AI server revenue $16.4B; backlog $95B | K24: 5 | L24: Server / rack orders | M24: 0 | N24: 3 | O24: https://www.dell.com/en-us/dt/corporate/newsroom/announcements/detailpage.press-releases~usa~2026~09~dell-technologies-delivers-second-quarter-fiscal-2027-financial-results.htm | P24: =DATE(YEAR(B24),MONTH(B24),1) | Q24: =IFERROR(INDEX('Market Data'!$B$2:$B$60,MATCH(P24,'Market Data'!$A$2:$A$60,0)),"") | R24: =IFERROR(INDEX('Market Data'!$B$2:$B$60,MATCH(EDATE(P24,1),'Market Data'!$A$2:$A$60,0))/Q24-1,"") | S24: =IFERROR(INDEX('Market Data'!$B$2:$B$60,MATCH(EDATE(P24,3),'Market Data'!$A$2:$A$60,0))/Q24-1,"") | T24: =IFERROR(INDEX('Market Data'!$B$2:$B$60,MATCH(EDATE(P24,6),'Market Data'!$A$2:$A$60,0))/Q24-1,"") | U24: =IFERROR(INDEX('Market Data'!$B$2:$B$60,MATCH(EDATE(P24,9),'Market Data'!$A$2:$A$60,0))/Q24-1,"") | V24: =IFERROR(MINIFS('Market Data'!$A$2:$A$60,'Market Data'!$A$2:$A$60,">"&P24,'Market Data'!$D$2:$D$60,1),"") | W24: =IF(V24="","",DATEDIF(P24,V24,"m")) | X24: Late confirmation / revenue stage; not treated as a leading backtest event.

Sheet Conversion Clock
A1: Physical Contract → Chip Revenue → Compute Revenue Clock
A2: The stages overlap. The model is a timing framework anchored to public supplier lead-times, not a deterministic sequence.
A4: # | B4: Stage | C4: Public Observable | D4: Lead to Compute Live Min (mo) | E4: Lead to Compute Live Max (mo) | F4: Lead to Chip Revenue Min (mo) | G4: Lead to Chip Revenue Max (mo) | H4: Research Read
A5: 1 | B5: Generation / utility commitment | C5: PPA, utility service, behind-the-meter generation contract, turbine/genset PO | D5: 12 | E5: 36 | F5: 6 | G5: 18 | H5: Earliest physical de-risking. Direct BTM can be faster than grid projects. CAT Monarch gives an explicit 8–19 month equipment-delivery window plus commissioning.
A6: 2 | B6: MEP / construction award | C6: EPC award, RPO/backlog, electrical/mechanical construction start | D6: 9 | E6: 24 | F6: 3 | G6: 15 | H6: Construction often spans multiple years; useful when data-center-specific, less useful when mixed end markets.
A7: 3 | B7: Electrical + cooling orders | C7: Switchgear, transformers, UPS, liquid cooling, busway, power distribution | D7: 9 | E7: 18 | F7: 3 | G7: 12 | H7: Potentially the best public leading signal in the power-constrained regime. Vertiv says most 2025 backlog is expected to ship within 12–18 months.
A8: 4 | B8: HBM / foundry / packaging allocation | C8: HBM agreements, wafer reservations, CoWoS capacity commitments | D8: 6 | E8: 18 | F8: 0 | G8: 12 | H8: Hardware procurement overlaps infrastructure build; not strictly sequential. SK hynix/Micron show customers reserve HBM roughly a year ahead.
A9: 5 | B9: Server / rack order | C9: AI-server PO, rack integration, ODM backlog | D9: 1 | E9: 6 | F9: 0 | G9: 3 | H9: Late bridge from component allocation to delivered systems. Dell backlog/orders provide observable confirmation.
A10: 6 | B10: Chip vendor revenue | C10: Accelerator, memory, networking and foundry revenue recognition | D10: 0 | E10: 6 | F10: 0 | G10: 0 | H10: Usually recognized before or around server delivery/commissioning, not after the data center is fully operational.
A11: 7 | B11: Commissioning / compute revenue | C11: Power-on, rack burn-in, customer acceptance, cloud/compute billing | D11: 0 | E11: 3 | F11: 0 | G11: 0 | H11: T = compute live. Compute revenue begins only after power + cooling + systems are ready.
A14: Relative timeline (T = compute live)
A15: Stage | B15: Earliest | C15: Latest | D15: T-24 | E15: T-23 | F15: T-22 | G15: T-21 | H15: T-20 | I15: T-19 | J15: T-18 | K15: T-17 | L15: T-16 | M15: T-15 | N15: T-14 | O15: T-13 | P15: T-12 | Q15: T-11 | R15: T-10 | S15: T-9 | T15: T-8 | U15: T-7 | V15: T-6 | W15: T-5 | X15: T-4 | Y15: T-3 | Z15: T-2 | AA15: T-1 | AB15: T0 | AC15: T+1 | AD15: T+2 | AE15: T+3
A16: Power / generation | B16: -24 | C16: -9 | D16: ● | E16: ● | F16: ● | G16: ● | H16: ● | I16: ● | J16: ● | K16: ● | L16: ● | M16: ● | N16: ● | O16: ● | P16: ● | Q16: ● | R16: ● | S16: ●
A17: MEP / construction | B17: -18 | C17: -6 | J17: ● | K17: ● | L17: ● | M17: ● | N17: ● | O17: ● | P17: ● | Q17: ● | R17: ● | S17: ● | T17: ● | U17: ● | V17: ●
A18: Electrical / cooling | B18: -18 | C18: -6 | J18: ● | K18: ● | L18: ● | M18: ● | N18: ● | O18: ● | P18: ● | Q18: ● | R18: ● | S18: ● | T18: ● | U18: ● | V18: ●
A19: HBM / foundry / packaging | B19: -18 | C19: -6 | J19: ● | K19: ● | L19: ● | M19: ● | N19: ● | O19: ● | P19: ● | Q19: ● | R19: ● | S19: ● | T19: ● | U19: ● | V19: ●
A20: Server / rack orders | B20: -6 | C20: -1 | V20: ● | W20: ● | X20: ● | Y20: ● | Z20: ● | AA20: ●
A21: Chip vendor revenue | B21: -6 | C21: 0 | V21: ● | W21: ● | X21: ● | Y21: ● | Z21: ● | AA21: ● | AB21: ●
A22: Commissioning | B22: -2 | C22: 0 | Z22: ● | AA22: ● | AB22: ●
A23: Compute revenue | B23: 0 | C23: 3 | AB23: ● | AC23: ● | AD23: ● | AE23: ●

Sheet Event Study
A1: Exploratory Event Study: Do Physical Infrastructure Signals Lead SOXX?
A2: Forward returns use event-month SOXX closes. Events are clustered and non-independent; results are hypothesis-generating, not causal evidence.
A4: Summary statistics
A5: Sample | B5: N | C5: Avg 1M | D5: Avg 3M | E5: Median 3M | F5: Avg 6M | G5: Median 6M | H5: Avg months to next >=10% SOXX month
A6: Demand-led | B6: =COUNTIFS('Supplier Signals'!$G$2:$G$100,1,'Supplier Signals'!$H$2:$H$100,"Demand-led") | C6: =AVERAGEIFS('Supplier Signals'!$R$2:$R$100,'Supplier Signals'!$G$2:$G$100,1,'Supplier Signals'!$H$2:$H$100,"Demand-led") | D6: =AVERAGEIFS('Supplier Signals'!$S$2:$S$100,'Supplier Signals'!$G$2:$G$100,1,'Supplier Signals'!$H$2:$H$100,"Demand-led") | E6: =MEDIAN(M14:M27) | F6: =AVERAGEIFS('Supplier Signals'!$T$2:$T$100,'Supplier Signals'!$G$2:$G$100,1,'Supplier Signals'!$H$2:$H$100,"Demand-led") | G6: =MEDIAN(N14:N27) | H6: =AVERAGEIFS('Supplier Signals'!$W$2:$W$100,'Supplier Signals'!$G$2:$G$100,1,'Supplier Signals'!$H$2:$H$100,"Demand-led")
A7: Transition | B7: =COUNTIFS('Supplier Signals'!$G$2:$G$100,1,'Supplier Signals'!$H$2:$H$100,"Transition") | C7: =AVERAGEIFS('Supplier Signals'!$R$2:$R$100,'Supplier Signals'!$G$2:$G$100,1,'Supplier Signals'!$H$2:$H$100,"Transition") | D7: =AVERAGEIFS('Supplier Signals'!$S$2:$S$100,'Supplier Signals'!$G$2:$G$100,1,'Supplier Signals'!$H$2:$H$100,"Transition") | E7: =D7 | F7: =AVERAGEIFS('Supplier Signals'!$T$2:$T$100,'Supplier Signals'!$G$2:$G$100,1,'Supplier Signals'!$H$2:$H$100,"Transition") | G7: =F7 | H7: =AVERAGEIFS('Supplier Signals'!$W$2:$W$100,'Supplier Signals'!$G$2:$G$100,1,'Supplier Signals'!$H$2:$H$100,"Transition")
A8: Power-constrained | B8: =COUNTIFS('Supplier Signals'!$G$2:$G$100,1,'Supplier Signals'!$H$2:$H$100,"Power-constrained") | C8: =AVERAGEIFS('Supplier Signals'!$R$2:$R$100,'Supplier Signals'!$G$2:$G$100,1,'Supplier Signals'!$H$2:$H$100,"Power-constrained") | D8: =AVERAGEIFS('Supplier Signals'!$S$2:$S$100,'Supplier Signals'!$G$2:$G$100,1,'Supplier Signals'!$H$2:$H$100,"Power-constrained") | E8: =MEDIAN(O14:O27) | F8: =AVERAGEIFS('Supplier Signals'!$T$2:$T$100,'Supplier Signals'!$G$2:$G$100,1,'Supplier Signals'!$H$2:$H$100,"Power-constrained") | G8: =MEDIAN(P14:P27) | H8: =AVERAGEIFS('Supplier Signals'!$W$2:$W$100,'Supplier Signals'!$G$2:$G$100,1,'Supplier Signals'!$H$2:$H$100,"Power-constrained")
A9: All upstream | B9: =COUNTIF('Supplier Signals'!$G$2:$G$100,1) | C9: =AVERAGEIF('Supplier Signals'!$G$2:$G$100,1,'Supplier Signals'!$R$2:$R$100) | D9: =AVERAGEIF('Supplier Signals'!$G$2:$G$100,1,'Supplier Signals'!$S$2:$S$100) | E9: =MEDIAN(G14:G27) | F9: =AVERAGEIF('Supplier Signals'!$G$2:$G$100,1,'Supplier Signals'!$T$2:$T$100) | G9: =MEDIAN(H14:H27) | H9: =AVERAGEIF('Supplier Signals'!$G$2:$G$100,1,'Supplier Signals'!$W$2:$W$100)
A12: Backtest event detail (upstream physical only)
A13: Event Date | B13: Company | C13: Layer | D13: Regime | E13: Event | F13: 1M | G13: 3M | H13: 6M | I13: 9M | J13: Next >=10% month | K13: Lead (mo) | L13: Source
A14: ='Supplier Signals'!B2 | B14: ='Supplier Signals'!C2 | C14: ='Supplier Signals'!E2 | D14: ='Supplier Signals'!H2 | E14: ='Supplier Signals'!I2 | F14: ='Supplier Signals'!R2 | G14: ='Supplier Signals'!S2 | H14: ='Supplier Signals'!T2 | I14: ='Supplier Signals'!U2 | J14: ='Supplier Signals'!V2 | K14: ='Supplier Signals'!W2 | L14: ='Supplier Signals'!O2 | M14: =IF($D14="Demand-led",$G14,"") | N14: =IF($D14="Demand-led",$H14,"") | O14: =IF($D14="Power-constrained",$G14,"") | P14: =IF($D14="Power-constrained",$H14,"")
A15: ='Supplier Signals'!B3 | B15: ='Supplier Signals'!C3 | C15: ='Supplier Signals'!E3 | D15: ='Supplier Signals'!H3 | E15: ='Supplier Signals'!I3 | F15: ='Supplier Signals'!R3 | G15: ='Supplier Signals'!S3 | H15: ='Supplier Signals'!T3 | I15: ='Supplier Signals'!U3 | J15: ='Supplier Signals'!V3 | K15: ='Supplier Signals'!W3 | L15: ='Supplier Signals'!O3 | M15: =IF($D15="Demand-led",$G15,"") | N15: =IF($D15="Demand-led",$H15,"") | O15: =IF($D15="Power-constrained",$G15,"") | P15: =IF($D15="Power-constrained",$H15,"")
A16: ='Supplier Signals'!B4 | B16: ='Supplier Signals'!C4 | C16: ='Supplier Signals'!E4 | D16: ='Supplier Signals'!H4 | E16: ='Supplier Signals'!I4 | F16: ='Supplier Signals'!R4 | G16: ='Supplier Signals'!S4 | H16: ='Supplier Signals'!T4 | I16: ='Supplier Signals'!U4 | J16: ='Supplier Signals'!V4 | K16: ='Supplier Signals'!W4 | L16: ='Supplier Signals'!O4 | M16: =IF($D16="Demand-led",$G16,"") | N16: =IF($D16="Demand-led",$H16,"") | O16: =IF($D16="Power-constrained",$G16,"") | P16: =IF($D16="Power-constrained",$H16,"")
A17: ='Supplier Signals'!B7 | B17: ='Supplier Signals'!C7 | C17: ='Supplier Signals'!E7 | D17: ='Supplier Signals'!H7 | E17: ='Supplier Signals'!I7 | F17: ='Supplier Signals'!R7 | G17: ='Supplier Signals'!S7 | H17: ='Supplier Signals'!T7 | I17: ='Supplier Signals'!U7 | J17: ='Supplier Signals'!V7 | K17: ='Supplier Signals'!W7 | L17: ='Supplier Signals'!O7 | M17: =IF($D17="Demand-led",$G17,"") | N17: =IF($D17="Demand-led",$H17,"") | O17: =IF($D17="Power-constrained",$G17,"") | P17: =IF($D17="Power-constrained",$H17,"")
A18: ='Supplier Signals'!B10 | B18: ='Supplier Signals'!C10 | C18: ='Supplier Signals'!E10 | D18: ='Supplier Signals'!H10 | E18: ='Supplier Signals'!I10 | F18: ='Supplier Signals'!R10 | G18: ='Supplier Signals'!S10 | H18: ='Supplier Signals'!T10 | I18: ='Supplier Signals'!U10 | J18: ='Supplier Signals'!V10 | K18: ='Supplier Signals'!W10 | L18: ='Supplier Signals'!O10 | M18: =IF($D18="Demand-led",$G18,"") | N18: =IF($D18="Demand-led",$H18,"") | O18: =IF($D18="Power-constrained",$G18,"") | P18: =IF($D18="Power-constrained",$H18,"")
A19: ='Supplier Signals'!B11 | B19: ='Supplier Signals'!C11 | C19: ='Supplier Signals'!E11 | D19: ='Supplier Signals'!H11 | E19: ='Supplier Signals'!I11 | F19: ='Supplier Signals'!R11 | G19: ='Supplier Signals'!S11 | H19: ='Supplier Signals'!T11 | I19: ='Supplier Signals'!U11 | J19: ='Supplier Signals'!V11 | K19: ='Supplier Signals'!W11 | L19: ='Supplier Signals'!O11 | M19: =IF($D19="Demand-led",$G19,"") | N19: =IF($D19="Demand-led",$H19,"") | O19: =IF($D19="Power-constrained",$G19,"") | P19: =IF($D19="Power-constrained",$H19,"")
A20: ='Supplier Signals'!B13 | B20: ='Supplier Signals'!C13 | C20: ='Supplier Signals'!E13 | D20: ='Supplier Signals'!H13 | E20: ='Supplier Signals'!I13 | F20: ='Supplier Signals'!R13 | G20: ='Supplier Signals'!S13 | H20: ='Supplier Signals'!T13 | I20: ='Supplier Signals'!U13 | J20: ='Supplier Signals'!V13 | K20: ='Supplier Signals'!W13 | L20: ='Supplier Signals'!O13 | M20: =IF($D20="Demand-led",$G20,"") | N20: =IF($D20="Demand-led",$H20,"") | O20: =IF($D20="Power-constrained",$G20,"") | P20: =IF($D20="Power-constrained",$H20,"")
A21: ='Supplier Signals'!B14 | B21: ='Supplier Signals'!C14 | C21: ='Supplier Signals'!E14 | D21: ='Supplier Signals'!H14 | E21: ='Supplier Signals'!I14 | F21: ='Supplier Signals'!R14 | G21: ='Supplier Signals'!S14 | H21: ='Supplier Signals'!T14 | I21: ='Supplier Signals'!U14 | J21: ='Supplier Signals'!V14 | K21: ='Supplier Signals'!W14 | L21: ='Supplier Signals'!O14 | M21: =IF($D21="Demand-led",$G21,"") | N21: =IF($D21="Demand-led",$H21,"") | O21: =IF($D21="Power-constrained",$G21,"") | P21: =IF($D21="Power-constrained",$H21,"")
A22: ='Supplier Signals'!B15 | B22: ='Supplier Signals'!C15 | C22: ='Supplier Signals'!E15 | D22: ='Supplier Signals'!H15 | E22: ='Supplier Signals'!I15 | F22: ='Supplier Signals'!R15 | G22: ='Supplier Signals'!S15 | H22: ='Supplier Signals'!T15 | I22: ='Supplier Signals'!U15 | J22: ='Supplier Signals'!V15 | K22: ='Supplier Signals'!W15 | L22: ='Supplier Signals'!O15 | M22: =IF($D22="Demand-led",$G22,"") | N22: =IF($D22="Demand-led",$H22,"") | O22: =IF($D22="Power-constrained",$G22,"") | P22: =IF($D22="Power-constrained",$H22,"")
A23: ='Supplier Signals'!B16 | B23: ='Supplier Signals'!C16 | C23: ='Supplier Signals'!E16 | D23: ='Supplier Signals'!H16 | E23: ='Supplier Signals'!I16 | F23: ='Supplier Signals'!R16 | G23: ='Supplier Signals'!S16 | H23: ='Supplier Signals'!T16 | I23: ='Supplier Signals'!U16 | J23: ='Supplier Signals'!V16 | K23: ='Supplier Signals'!W16 | L23: ='Supplier Signals'!O16 | M23: =IF($D23="Demand-led",$G23,"") | N23: =IF($D23="Demand-led",$H23,"") | O23: =IF($D23="Power-constrained",$G23,"") | P23: =IF($D23="Power-constrained",$H23,"")
A24: ='Supplier Signals'!B17 | B24: ='Supplier Signals'!C17 | C24: ='Supplier Signals'!E17 | D24: ='Supplier Signals'!H17 | E24: ='Supplier Signals'!I17 | F24: ='Supplier Signals'!R17 | G24: ='Supplier Signals'!S17 | H24: ='Supplier Signals'!T17 | I24: ='Supplier Signals'!U17 | J24: ='Supplier Signals'!V17 | K24: ='Supplier Signals'!W17 | L24: ='Supplier Signals'!O17 | M24: =IF($D24="Demand-led",$G24,"") | N24: =IF($D24="Demand-led",$H24,"") | O24: =IF($D24="Power-constrained",$G24,"") | P24: =IF($D24="Power-constrained",$H24,"")
A25: ='Supplier Signals'!B18 | B25: ='Supplier Signals'!C18 | C25: ='Supplier Signals'!E18 | D25: ='Supplier Signals'!H18 | E25: ='Supplier Signals'!I18 | F25: ='Supplier Signals'!R18 | G25: ='Supplier Signals'!S18 | H25: ='Supplier Signals'!T18 | I25: ='Supplier Signals'!U18 | J25: ='Supplier Signals'!V18 | K25: ='Supplier Signals'!W18 | L25: ='Supplier Signals'!O18 | M25: =IF($D25="Demand-led",$G25,"") | N25: =IF($D25="Demand-led",$H25,"") | O25: =IF($D25="Power-constrained",$G25,"") | P25: =IF($D25="Power-constrained",$H25,"")
A26: ='Supplier Signals'!B19 | B26: ='Supplier Signals'!C19 | C26: ='Supplier Signals'!E19 | D26: ='Supplier Signals'!H19 | E26: ='Supplier Signals'!I19 | F26: ='Supplier Signals'!R19 | G26: ='Supplier Signals'!S19 | H26: ='Supplier Signals'!T19 | I26: ='Supplier Signals'!U19 | J26: ='Supplier Signals'!V19 | K26: ='Supplier Signals'!W19 | L26: ='Supplier Signals'!O19 | M26: =IF($D26="Demand-led",$G26,"") | N26: =IF($D26="Demand-led",$H26,"") | O26: =IF($D26="Power-constrained",$G26,"") | P26: =IF($D26="Power-constrained",$H26,"")
A27: ='Supplier Signals'!B20 | B27: ='Supplier Signals'!C20 | C27: ='Supplier Signals'!E20 | D27: ='Supplier Signals'!H20 | E27: ='Supplier Signals'!I20 | F27: ='Supplier Signals'!R20 | G27: ='Supplier Signals'!S20 | H27: ='Supplier Signals'!T20 | I27: ='Supplier Signals'!U20 | J27: ='Supplier Signals'!V20 | K27: ='Supplier Signals'!W20 | L27: ='Supplier Signals'!O20 | M27: =IF($D27="Demand-led",$G27,"") | N27: =IF($D27="Demand-led",$H27,"") | O27: =IF($D27="Power-constrained",$G27,"") | P27: =IF($D27="Power-constrained",$H27,"")

Sheet Case Studies
A1: Case Studies: What the Sequence Looked Like
A3: Cycle / Test | B3: Date | C3: Layer | D3: Observed Signal | E3: What Followed | F3: Read
A4: 2023–24 demand-led | B4: 10/25/2023 | C4: Cooling / power | D4: Vertiv orders +11%; backlog $5.0B | E4: SOXX +16.1% in Nov; +32.7% over next 3 months | F4: Useful, but AI-chip demand itself was already driving the build. Physical signals were often concurrent with semis.
A5: 2023–24 demand-led | B5: 2/21/2024 | C5: Cooling / power | D5: Vertiv orders +23%; backlog $5.5B | E5: Dell AI backlog $2.9B on 2/29; SK hynix current-year HBM sold out | F5: Bridge from facility orders into systems/memory was visible, but semis were already in an upcycle.
A6: 2023–24 demand-led | B6: 4/24/2024 | C6: Cooling / power | D6: Vertiv orders +60%; B2B 1.5x | E6: Dell orders $2.6B / shipments $1.7B on 5/30; TSMC CoWoS expansion on 7/18 | F6: Strong confirmation, not a clean early entry signal.
A7: 2025–26 power-constrained | B7: 7/30/2025 | C7: Cooling / power | D7: Vertiv orders +15% YoY / +11% sequential | E7: SOXX +28.0% over next 3 months | F7: Physical infrastructure reacceleration became visible before the next semiconductor acceleration.
A8: 2025–26 power-constrained | B8: 8/7–8/21/2025 | C8: Generation | D8: Caterpillar signs 4 GW Joule agreement and up-to-1 GW Hunt alliance | E8: Vertiv orders +60% in Oct; Eaton electrical orders data-center-driven in Nov | F8: Power de-risking visibly preceded the later electrical/cooling order explosion.
A9: 2025–26 power-constrained | B9: 10/22/2025 | C9: Cooling / power | D9: Vertiv orders +60%; B2B 1.4x; backlog $9.5B | E9: SOXX +13.1% over 3 months; +50.8% over 6 months | F9: This is close to the signal we want: physical orders accelerate while the next semi leg is not yet fully priced.
A10: 2025–26 power-constrained | B10: 1/28–2/11/2026 | C10: Generation + electrical + cooling | D10: CAT 2 GW firm order; Eaton DC orders +~200%; Vertiv orders +252% | E10: SOXX Feb close $351.91 → Jun $640.76 (~+82%); Dell AI revenue/order surge followed | F10: Strongest preliminary evidence that physical-order confirmation can front-run a semi re-rating in a power-gated regime.
A11: Forward live test | B11: 1/28/2026 onward | C11: Generation | D11: Monarch 2 GW gensets deliver Sep-26 through Aug-27; commissioning within months | E11: Future chip/server procurement should be visible before power-on if the model is right | F11: Track HBM/CoWoS/GPU/server commitments against this explicit delivery clock. This is a true forward test, not a backtest.
A12: Current late-stage | B12: 9/1/2026 | C12: Servers / racks | D12: Dell: $60.9B AI orders, $16.4B revenue, $95B backlog | E12: Hardware monetization is already obvious | F12: Too late to be the early signal. We want the upstream VRT/ETN/CAT/MEP inflection before this stage.

Sheet Sources & Method
A1: Sources, Definitions & Methodology
A3: Method
A4: Question | B4: Can public physical-infrastructure orders provide a timing signal before semiconductor equity/revenue cycles?
A5: Primary unit of observation | B5: A dated public disclosure: generation contract, electrical/cooling order acceleration, construction backlog, HBM/packaging allocation, or AI server order/revenue disclosure.
A6: Backtest set | B6: Only rows marked Backtest? = 1. Bridge/confirmation rows are kept for chronology but excluded from upstream-return averages.
A7: Market proxy | B7: SOXX month-end close. Forward returns are measured from the event month-end, so timing is intentionally coarse.
A8: Strong month definition | B8: SOXX calendar-month return >= 10%. Used only as a simple clock marker, not as a statistical threshold.
A9: Regime split | B9: Demand-led = 2023–24; Transition = early 2025; Power-constrained = Jul-2025 onward. This split is thesis-driven and ex post, so it can overstate apparent differences.
A10: Critical limitation | B10: Events are clustered around the same industry cycle and are not independent. This workbook does not prove causality. It is designed to identify a repeatable sequence for forward monitoring.
A11: What would validate the thesis forward | B11: A new generation/electrical/cooling order inflection occurs while SOXX/semis are still weak; HBM/CoWoS/server orders then rise within the predicted window; chip revenue follows before compute commissioning.
A14: Clock anchors
A15: Power / generation | B15: CAT Monarch 2 GW purchase agreement; equipment deliveries Sep-2026 to Aug-2027, then commissioning within months. | C15: https://investors.caterpillar.com/news/news-details/2026/American-Intelligence--Power-Forms-Strategic-Alliance-with-Caterpillar-and-Boyd-CAT-to-Deploy-2-Gigawatts-of-Dedicated-Power-for-Hyperscale-AI-Infrastructure/default.aspx
A16: Cooling / electrical | B16: Vertiv 2025 10-K: majority of $15B backlog considered firm and expected to ship within 12–18 months. | C16: https://www.sec.gov/Archives/edgar/data/1674101/000167410126000008/vrt-20251231.htm
A17: HBM | B17: SK hynix Feb-2024: planned current-year HBM sold out; already preparing for following year. | C17: https://news.skhynix.com/en/new-leadership-spotlight-vice-president-kitae-kim-head-of-hbm-sales-marketing/
A18: HBM | B18: Micron Mar-2025: 2025 HBM sold out; negotiating customer agreements for 2026 demand. | C18: https://investors.micron.com/static-files/52ce0c07-49dc-4eab-b1d2-a67bde373bca
A19: Advanced packaging | B19: TSMC Jul-2024: CoWoS more than doubled in 2024; planned to double or more again in 2025. | C19: https://investor.tsmc.com/english/encrypt/files/encrypt_file/reports/2024-08/5122725a56670882d777a8e8bfe0ed247cc55330/TSMC%202Q24%20Transcript.pdf
A20: Construction | B20: EMCOR: large projects can span multiple years; 2025 data-center construction drove network/communications growth. | C20: https://www.sec.gov/Archives/edgar/data/105634/000010563426000025/eme-20251231.htm
A21: Server systems | B21: Dell May-2024: AI orders $2.6B, shipments $1.7B, backlog $3.8B. | C21: https://investors.delltechnologies.com/news-releases/news-release-details/dell-technologies-delivers-first-quarter-fiscal-2025-financial

Sheet Assumptions
A1: Dual-Clock Assumptions
A2: Blue cells are user-adjustable. Imported benchmarks are green. Formulas throughout the workbook reference these controls rather than hard-coded thresholds.
A4: POWER → IT CONVERSION
A5: Assumption | B5: Value | C5: Unit | D5: Use | E5: Source / rationale
A6: Default generation availability | B6: 0.95 | C6: factor | D6: Gross generation → firm generation | E6: User control; set project-specific values when disclosed.
A7: Default reserve / redundancy factor | B7: 0.85 | C7: factor | D7: Firm generation → usable facility load | E7: User control; captures N+1 / reserve headroom.
A8: Default PUE | B8: 1.15 | C8: PUE | D8: Facility MW → IT MW | E8: Modern AI data-center working assumption; override per project.
A9: Hopper NVIDIA content / IT GW | B9: 18000000000 | C9: $/GW | D9: Dollar → implied IT GW | E9: NVIDIA Q2 FY27 transcript: roughly $18B/GW with Hopper.
A10: Blackwell NVIDIA content / IT GW | B10: 25000000000 | C10: $/GW | D10: Dollar → implied IT GW | E10: NVIDIA Q2 FY27 transcript: roughly $25B/GW with Blackwell.
A11: Vera Rubin NVIDIA content / IT GW | B11: 40000000000 | C11: $/GW | D11: Dollar → implied IT GW | E11: NVIDIA Q2 FY27 transcript: roughly $40B/GW with Vera Rubin.
A14: SELL-CLOCK THRESHOLDS
A15: Metric | B15: Green max | C15: Watch max | D15: Yellow max | E15: Orange max | F15: Red | G15: Notes
A16: Forward 6M hardware / power | B16: 0.85 | C16: 1.05 | D16: 1.25 | E16: 1.5 | F16: >1.50 | G16: Heuristic starting bands. Calibrate as more project-level delivery data accumulates.
A17: Sell convergence score | B17: 1 | C17: 2 | D17: 3 | E17: 4 | F17: 5 | G17: Counts independent warning categories, not raw number of headlines.
A20: WARNING CATEGORIES
A21: Category | B21: Definition | C21: Historical example | D21: Score contribution
A22: Power / construction slippage | B22: CODs, permitting, turbines, transformers or construction fall behind planned delivery. | C22: JPM May 4: >60% of 2027 capacity not started; 7% delayed. | D22: 1
A23: Build-throughput gap | B23: Physical capacity under construction is small relative to backlog / hardware need. | C23: Eaton May 5: 32 GW under construction vs 228 GW backlog. | D23: 1
A24: Chip revenue acceleration | B24: Accelerator/HBM/networking revenue is accelerating into the constrained build. | C24: NVIDIA May 20: $75.2B Data Center revenue, +92% YoY. | D24: 1
A25: Server / rack delivery acceleration | B25: Systems orders, revenue or backlog jump faster than visible energization. | C25: Dell May 28: $24.4B AI orders; $16.1B AI server revenue; $51.3B backlog. | D25: 1
A26: System / regulatory intervention | B26: Grid operator, FERC, utility or government acts because large-load integration is failing/slowing. | C26: FERC June 18: all six RTO/ISOs ordered to justify/reform large-load rules. | D26: 1

Sheet Hardware Deliveries
A1: Hardware Delivery Ledger
A2: Use only delivery schedules that can be tied to a time window. The model supports direct MW, rack × kW, or dollar-value conversion. Rows without a credible delivery window should stay excluded from coverage.
A4: Include? | B4: Vendor | C4: Project / customer | D4: Layer | E4: Conversion method | F4: Delivery start | G4: Delivery end | H4: Quantity / $ value | I4: kW per rack | J4: $/IT GW benchmark | K4: Implied IT MW | L4: Duration (mo) | M4: MW / month | N4: Confidence | O4: Source URL | P4: Notes
A5: 0 | B5: NVIDIA | C5: Vera Rubin hyperscaler / AI-cloud POs | D5: Accelerator + network | E5: Dollar / GW | F5: 46235 | J5: 40000000000 | K5: =IF(A5<>1,"",IF(E5="Direct IT MW",H5,IF(E5="Rack x kW",H5*I5/1000,IF(E5="Dollar / GW",H5/J5*1000,"")))) | L5: =IF(OR(F5="",G5=""),"",DATEDIF(F5,G5,"m")+1) | M5: =IF(OR(K5="",L5=""),"",K5/L5) | N5: 5 | O5: https://investor.nvidia.com/files/content_files/TRANSCRIPT_-NVIDIA-Corp-NVDA-US-Q2-2027-Earnings-Call-26-August-2026-5_00-PM-ET.pdf | P5: POs from every major hyperscaler, AI cloud and system OEM; production shipments commenced Aug-26. Add disclosed delivery window/value when available.
A6: 0 | B6: Dell | C6: Q2 FY27 AI server backlog | D6: Servers / racks | E6: Dollar / GW | F6: 46235 | H6: 95000000000 | K6: =IF(A6<>1,"",IF(E6="Direct IT MW",H6,IF(E6="Rack x kW",H6*I6/1000,IF(E6="Dollar / GW",H6/J6*1000,"")))) | L6: =IF(OR(F6="",G6=""),"",DATEDIF(F6,G6,"m")+1) | M6: =IF(OR(K6="",L6=""),"",K6/L6) | N6: 5 | O6: https://investors.delltechnologies.com/static-files/a24f97e4-63b2-460d-a4be-44738826e8ce | P6: Backlog is a strong numerator proxy but delivery schedule and architecture mix must be supplied before coverage use.
A7: 0 | K7: =IF(A7<>1,"",IF(E7="Direct IT MW",H7,IF(E7="Rack x kW",H7*I7/1000,IF(E7="Dollar / GW",H7/J7*1000,"")))) | L7: =IF(OR(F7="",G7=""),"",DATEDIF(F7,G7,"m")+1) | M7: =IF(OR(K7="",L7=""),"",K7/L7)
A8: 0 | K8: =IF(A8<>1,"",IF(E8="Direct IT MW",H8,IF(E8="Rack x kW",H8*I8/1000,IF(E8="Dollar / GW",H8/J8*1000,"")))) | L8: =IF(OR(F8="",G8=""),"",DATEDIF(F8,G8,"m")+1) | M8: =IF(OR(K8="",L8=""),"",K8/L8)
A9: 0 | K9: =IF(A9<>1,"",IF(E9="Direct IT MW",H9,IF(E9="Rack x kW",H9*I9/1000,IF(E9="Dollar / GW",H9/J9*1000,"")))) | L9: =IF(OR(F9="",G9=""),"",DATEDIF(F9,G9,"m")+1) | M9: =IF(OR(K9="",L9=""),"",K9/L9)
A10: 0 | K10: =IF(A10<>1,"",IF(E10="Direct IT MW",H10,IF(E10="Rack x kW",H10*I10/1000,IF(E10="Dollar / GW",H10/J10*1000,"")))) | L10: =IF(OR(F10="",G10=""),"",DATEDIF(F10,G10,"m")+1) | M10: =IF(OR(K10="",L10=""),"",K10/L10)
A11: 0 | K11: =IF(A11<>1,"",IF(E11="Direct IT MW",H11,IF(E11="Rack x kW",H11*I11/1000,IF(E11="Dollar / GW",H11/J11*1000,"")))) | L11: =IF(OR(F11="",G11=""),"",DATEDIF(F11,G11,"m")+1) | M11: =IF(OR(K11="",L11=""),"",K11/L11)
A12: 0 | K12: =IF(A12<>1,"",IF(E12="Direct IT MW",H12,IF(E12="Rack x kW",H12*I12/1000,IF(E12="Dollar / GW",H12/J12*1000,"")))) | L12: =IF(OR(F12="",G12=""),"",DATEDIF(F12,G12,"m")+1) | M12: =IF(OR(K12="",L12=""),"",K12/L12)
A13: 0 | K13: =IF(A13<>1,"",IF(E13="Direct IT MW",H13,IF(E13="Rack x kW",H13*I13/1000,IF(E13="Dollar / GW",H13/J13*1000,"")))) | L13: =IF(OR(F13="",G13=""),"",DATEDIF(F13,G13,"m")+1) | M13: =IF(OR(K13="",L13=""),"",K13/L13)
A14: 0 | K14: =IF(A14<>1,"",IF(E14="Direct IT MW",H14,IF(E14="Rack x kW",H14*I14/1000,IF(E14="Dollar / GW",H14/J14*1000,"")))) | L14: =IF(OR(F14="",G14=""),"",DATEDIF(F14,G14,"m")+1) | M14: =IF(OR(K14="",L14=""),"",K14/L14)
A15: 0 | K15: =IF(A15<>1,"",IF(E15="Direct IT MW",H15,IF(E15="Rack x kW",H15*I15/1000,IF(E15="Dollar / GW",H15/J15*1000,"")))) | L15: =IF(OR(F15="",G15=""),"",DATEDIF(F15,G15,"m")+1) | M15: =IF(OR(K15="",L15=""),"",K15/L15)
A16: 0 | K16: =IF(A16<>1,"",IF(E16="Direct IT MW",H16,IF(E16="Rack x kW",H16*I16/1000,IF(E16="Dollar / GW",H16/J16*1000,"")))) | L16: =IF(OR(F16="",G16=""),"",DATEDIF(F16,G16,"m")+1) | M16: =IF(OR(K16="",L16=""),"",K16/L16)
A17: 0 | K17: =IF(A17<>1,"",IF(E17="Direct IT MW",H17,IF(E17="Rack x kW",H17*I17/1000,IF(E17="Dollar / GW",H17/J17*1000,"")))) | L17: =IF(OR(F17="",G17=""),"",DATEDIF(F17,G17,"m")+1) | M17: =IF(OR(K17="",L17=""),"",K17/L17)
A18: 0 | K18: =IF(A18<>1,"",IF(E18="Direct IT MW",H18,IF(E18="Rack x kW",H18*I18/1000,IF(E18="Dollar / GW",H18/J18*1000,"")))) | L18: =IF(OR(F18="",G18=""),"",DATEDIF(F18,G18,"m")+1) | M18: =IF(OR(K18="",L18=""),"",K18/L18)
... A56: 0 | K56: =IF(A56<>1,"",IF(E56="Direct IT MW",H56,IF(E56="Rack x kW",H56*I56/1000,IF(E56="Dollar / GW",H56/J56*1000,"")))) | L56: =IF(OR(F56="",G56=""),"",DATEDIF(F56,G56,"m")+1) | M56: =IF(OR(K56="",L56=""),"",K56/L56)

Sheet Power Deliveries
A1: Power / Energization Ledger
A2: This is the denominator. Count only power that has a credible construction/delivery clock. Gross generation is converted to usable IT MW through availability, reserve headroom and PUE.
A4: Include? | B4: Provider | C4: Project | D4: Power type | E4: Delivery start | F4: Delivery end | G4: Gross MW | H4: Availability | I4: Reserve / redundancy | J4: PUE | K4: Usable IT MW | L4: Duration (mo) | M4: IT MW / month | N4: Status | O4: Confidence | P4: Source URL | Q4: Notes
A5: 1 | B5: Caterpillar / AIP | C5: Monarch Compute Campus | D5: Behind-the-meter gas gensets | E5: 46266 | F5: 46600 | G5: 2000 | H5: =Assumptions!$B$6 | I5: =Assumptions!$B$7 | J5: =Assumptions!$B$8 | K5: =IF(A5<>1,"",G5*H5*I5/J5) | L5: =IF(OR(E5="",F5=""),"",DATEDIF(E5,F5,"m")+1) | M5: =IF(OR(K5="",L5=""),"",K5/L5) | N5: Equipment deliveries contracted | O5: 5 | P5: https://investors.caterpillar.com/news/news-details/2026/American-Intelligence--Power-Forms-Strategic-Alliance-with-Caterpillar-and-Boyd-CAT-to-Deploy-2-Gigawatts-of-Dedicated-Power-for-Hyperscale-AI-Infrastructure/default.aspx | Q5: 2 GW ordered; deliveries Sep-26 through Aug-27; power delivery begins 2026 and 2 GW online in 2027.
A6: 0 | H6: =Assumptions!$B$6 | I6: =Assumptions!$B$7 | J6: =Assumptions!$B$8 | K6: =IF(A6<>1,"",G6*H6*I6/J6) | L6: =IF(OR(E6="",F6=""),"",DATEDIF(E6,F6,"m")+1) | M6: =IF(OR(K6="",L6=""),"",K6/L6)
A7: 0 | H7: =Assumptions!$B$6 | I7: =Assumptions!$B$7 | J7: =Assumptions!$B$8 | K7: =IF(A7<>1,"",G7*H7*I7/J7) | L7: =IF(OR(E7="",F7=""),"",DATEDIF(E7,F7,"m")+1) | M7: =IF(OR(K7="",L7=""),"",K7/L7)
A8: 0 | H8: =Assumptions!$B$6 | I8: =Assumptions!$B$7 | J8: =Assumptions!$B$8 | K8: =IF(A8<>1,"",G8*H8*I8/J8) | L8: =IF(OR(E8="",F8=""),"",DATEDIF(E8,F8,"m")+1) | M8: =IF(OR(K8="",L8=""),"",K8/L8)
A9: 0 | H9: =Assumptions!$B$6 | I9: =Assumptions!$B$7 | J9: =Assumptions!$B$8 | K9: =IF(A9<>1,"",G9*H9*I9/J9) | L9: =IF(OR(E9="",F9=""),"",DATEDIF(E9,F9,"m")+1) | M9: =IF(OR(K9="",L9=""),"",K9/L9)
A10: 0 | H10: =Assumptions!$B$6 | I10: =Assumptions!$B$7 | J10: =Assumptions!$B$8 | K10: =IF(A10<>1,"",G10*H10*I10/J10) | L10: =IF(OR(E10="",F10=""),"",DATEDIF(E10,F10,"m")+1) | M10: =IF(OR(K10="",L10=""),"",K10/L10)
A11: 0 | H11: =Assumptions!$B$6 | I11: =Assumptions!$B$7 | J11: =Assumptions!$B$8 | K11: =IF(A11<>1,"",G11*H11*I11/J11) | L11: =IF(OR(E11="",F11=""),"",DATEDIF(E11,F11,"m")+1) | M11: =IF(OR(K11="",L11=""),"",K11/L11)
A12: 0 | H12: =Assumptions!$B$6 | I12: =Assumptions!$B$7 | J12: =Assumptions!$B$8 | K12: =IF(A12<>1,"",G12*H12*I12/J12) | L12: =IF(OR(E12="",F12=""),"",DATEDIF(E12,F12,"m")+1) | M12: =IF(OR(K12="",L12=""),"",K12/L12)
A13: 0 | H13: =Assumptions!$B$6 | I13: =Assumptions!$B$7 | J13: =Assumptions!$B$8 | K13: =IF(A13<>1,"",G13*H13*I13/J13) | L13: =IF(OR(E13="",F13=""),"",DATEDIF(E13,F13,"m")+1) | M13: =IF(OR(K13="",L13=""),"",K13/L13)
A14: 0 | H14: =Assumptions!$B$6 | I14: =Assumptions!$B$7 | J14: =Assumptions!$B$8 | K14: =IF(A14<>1,"",G14*H14*I14/J14) | L14: =IF(OR(E14="",F14=""),"",DATEDIF(E14,F14,"m")+1) | M14: =IF(OR(K14="",L14=""),"",K14/L14)
A15: 0 | H15: =Assumptions!$B$6 | I15: =Assumptions!$B$7 | J15: =Assumptions!$B$8 | K15: =IF(A15<>1,"",G15*H15*I15/J15) | L15: =IF(OR(E15="",F15=""),"",DATEDIF(E15,F15,"m")+1) | M15: =IF(OR(K15="",L15=""),"",K15/L15)
A16: 0 | H16: =Assumptions!$B$6 | I16: =Assumptions!$B$7 | J16: =Assumptions!$B$8 | K16: =IF(A16<>1,"",G16*H16*I16/J16) | L16: =IF(OR(E16="",F16=""),"",DATEDIF(E16,F16,"m")+1) | M16: =IF(OR(K16="",L16=""),"",K16/L16)
A17: 0 | H17: =Assumptions!$B$6 | I17: =Assumptions!$B$7 | J17: =Assumptions!$B$8 | K17: =IF(A17<>1,"",G17*H17*I17/J17) | L17: =IF(OR(E17="",F17=""),"",DATEDIF(E17,F17,"m")+1) | M17: =IF(OR(K17="",L17=""),"",K17/L17)
... A55: 0 | H55: =Assumptions!$B$6 | I55: =Assumptions!$B$7 | J55: =Assumptions!$B$8 | K55: =IF(A55<>1,"",G55*H55*I55/J55) | L55: =IF(OR(E55="",F55=""),"",DATEDIF(E55,F55,"m")+1) | M55: =IF(OR(K55="",L55=""),"",K55/L55)

Sheet Coverage Calendar
A1: Hardware-to-Power Coverage Calendar
A2: Forward 6-month coverage compares scheduled hardware-equivalent IT MW with usable IT MW becoming available. A rising ratio is a potential sell-clock warning; it is not a demand signal.
A4: Month | B4: Hardware MW delivered | C4: Usable IT MW online | D4: Monthly gap MW | E4: Fwd 6M hardware MW | F4: Fwd 6M power MW | G4: Fwd 6M coverage | H4: Risk band | I4: Trailing 3M Δ ratio | J4: Comment | K4: Hardware rows used | L4: Power rows used
A5: 46023 | B5: =SUMIFS('Hardware Deliveries'!$M$5:$M$56,'Hardware Deliveries'!$A$5:$A$56,1,'Hardware Deliveries'!$F$5:$F$56,"<="&A5,'Hardware Deliveries'!$G$5:$G$56,">="&A5) | C5: =SUMIFS('Power Deliveries'!$M$5:$M$55,'Power Deliveries'!$A$5:$A$55,1,'Power Deliveries'!$E$5:$E$55,"<="&A5,'Power Deliveries'!$F$5:$F$55,">="&A5) | D5: =B5-C5 | E5: =SUM(B5:B10) | F5: =SUM(C5:C10) | G5: =IF(OR(K5=0,L5=0),"",E5/F5) | H5: =IF(G5="","NO DATA",IF(G5<=Assumptions!$B$16,"GREEN",IF(G5<=Assumptions!$C$16,"WATCH",IF(G5<=Assumptions!$D$16,"YELLOW",IF(G5<=Assumptions!$E$16,"ORANGE","RED"))))) | K5: =COUNTIFS('Hardware Deliveries'!$A$5:$A$56,1,'Hardware Deliveries'!$F$5:$F$56,"<="&A5,'Hardware Deliveries'!$G$5:$G$56,">="&A5) | L5: =COUNTIFS('Power Deliveries'!$A$5:$A$55,1,'Power Deliveries'!$E$5:$E$55,"<="&A5,'Power Deliveries'!$F$5:$F$55,">="&A5)
